<sdf version='1.7'>
  <model name='my_robot'>
    <link name='base_link'>
      <inertial>
        <pose>0.007562 0.002963 -0.035161 1.5708 -0 1.5708</pose>
        <mass>262.9</mass>
        <inertia>
          <ixx>65.0051</ixx>
          <ixy>-0.242417</ixy>
          <ixz>-0.513369</ixz>
          <iyy>86.0756</iyy>
          <iyz>-0.587528</iyz>
          <izz>33.8241</izz>
        </inertia>
      </inertial>
      <collision name='base_link_collision'>
        <pose>0 0 0 0 -0 0</pose>
        <geometry>
          <box>
            <size>1.5 1.03 0.36</size>
          </box>
        </geometry>
      </collision>
      <collision name='base_link_fixed_joint_lump__left_wheel_box_link_collision_1'>
        <pose>0 0.401 -0.24 1.5708 -0 0</pose>
        <geometry>
          <box>
            <size>1.25 0.4 0.23</size>
          </box>
        </geometry>
        <surface>
          <contact>
            <ode/>
          </contact>
          <friction>
            <ode>
              <mu>0.1</mu>
              <mu2>0.1</mu2>
            </ode>
          </friction>
        </surface>
      </collision>
      <collision name='base_link_fixed_joint_lump__left_wheel_additional_f_wheel_link_collision_2'>
        <pose>0.625 0.401 -0.24 1.5708 -0 0</pose>
        <geometry>
          <cylinder>
            <length>0.23</length>
            <radius>0.2</radius>
          </cylinder>
        </geometry>
        <surface>
          <contact>
            <ode/>
          </contact>
          <friction>
            <ode>
              <mu>0.2</mu>
              <mu2>0.2</mu2>
            </ode>
          </friction>
        </surface>
      </collision>
      <collision name='base_link_fixed_joint_lump__left_wheel_additional_r_wheel_link_collision_3'>
        <pose>-0.625 0.401 -0.24 1.5708 -0 0</pose>
        <geometry>
          <cylinder>
            <length>0.23</length>
            <radius>0.2</radius>
          </cylinder>
        </geometry>
        <surface>
          <contact>
            <ode/>
          </contact>
          <friction>
            <ode>
              <mu>0.2</mu>
              <mu2>0.2</mu2>
            </ode>
          </friction>
        </surface>
      </collision>
      <collision name='base_link_fixed_joint_lump__plate_link_collision_4'>
        <pose>0 0 0.2 0 -0 0</pose>
        <geometry>
          <box>
            <size>1.5 1.03 0.04</size>
          </box>
        </geometry>
        <surface>
          <contact>
            <ode/>
          </contact>
          <friction>
            <ode/>
          </friction>
        </surface>
      </collision>
      <collision name='base_link_fixed_joint_lump__right_wheel_box_link_collision_5'>
        <pose>0 -0.401 -0.24 1.5708 -0 0</pose>
        <geometry>
          <box>
            <size>1.25 0.4 0.23</size>
          </box>
        </geometry>
        <surface>
          <contact>
            <ode/>
          </contact>
          <friction>
            <ode>
              <mu>0.1</mu>
              <mu2>0.1</mu2>
            </ode>
          </friction>
        </surface>
      </collision>
      <collision name='base_link_fixed_joint_lump__right_wheel_additional_f_wheel_link_collision_6'>
        <pose>0.625 -0.401 -0.24 1.5708 -0 0</pose>
        <geometry>
          <cylinder>
            <length>0.23</length>
            <radius>0.2</radius>
          </cylinder>
        </geometry>
        <surface>
          <contact>
            <ode/>
          </contact>
          <friction>
            <ode>
              <mu>0.2</mu>
              <mu2>0.2</mu2>
            </ode>
          </friction>
        </surface>
      </collision>
      <collision name='base_link_fixed_joint_lump__right_wheel_additional_r_wheel_link_collision_7'>
        <pose>-0.625 -0.401 -0.24 1.5708 -0 0</pose>
        <geometry>
          <cylinder>
            <length>0.23</length>
            <radius>0.2</radius>
          </cylinder>
        </geometry>
        <surface>
          <contact>
            <ode/>
          </contact>
          <friction>
            <ode>
              <mu>0.2</mu>
              <mu2>0.2</mu2>
            </ode>
          </friction>
        </surface>
      </collision>
      <visual name='base_link_visual'>
        <pose>0 0 0 0 -0 0</pose>
        <geometry>
          <box>
            <size>1.5 1.03 0.36</size>
          </box>
        </geometry>
      </visual>
      <visual name='base_link_fixed_joint_lump__left_wheel_box_link_visual_1'>
        <pose>0 0.401 -0.24 1.5708 -0 0</pose>
        <geometry>
          <box>
            <size>1.25 0.4 0.23</size>
          </box>
        </geometry>
        <material>
          <script>
            <name>Gazebo/Black</name>
            <uri>file://media/materials/scripts/gazebo.material</uri>
          </script>
        </material>
      </visual>
      <visual name='base_link_fixed_joint_lump__left_wheel_additional_f_wheel_link_visual_2'>
        <pose>0.625 0.401 -0.24 1.5708 -0 0</pose>
        <geometry>
          <cylinder>
            <length>0.23</length>
            <radius>0.2</radius>
          </cylinder>
        </geometry>
        <material>
          <script>
            <name>Gazebo/Black</name>
            <uri>file://media/materials/scripts/gazebo.material</uri>
          </script>
        </material>
      </visual>
      <visual name='base_link_fixed_joint_lump__left_wheel_additional_r_wheel_link_visual_3'>
        <pose>-0.625 0.401 -0.24 1.5708 -0 0</pose>
        <geometry>
          <cylinder>
            <length>0.23</length>
            <radius>0.2</radius>
          </cylinder>
        </geometry>
        <material>
          <script>
            <name>Gazebo/Black</name>
            <uri>file://media/materials/scripts/gazebo.material</uri>
          </script>
        </material>
      </visual>
      <visual name='base_link_fixed_joint_lump__plate_link_visual_4'>
        <pose>0 0 0.2 0 -0 0</pose>
        <geometry>
          <box>
            <size>1.5 1.03 0.04</size>
          </box>
        </geometry>
        <material>
          <script>
            <name>Gazebo/Red</name>
            <uri>file://media/materials/scripts/gazebo.material</uri>
          </script>
        </material>
      </visual>
      <visual name='base_link_fixed_joint_lump__gps_link_visual_5'>
        <pose>0.675 0.44 0.27 0 -0 0</pose>
        <geometry>
          <box>
            <size>0.15 0.15 0.1</size>
          </box>
        </geometry>
      </visual>
      <visual name='base_link_fixed_joint_lump__imu_link_visual_6'>
        <pose>0.74 -0.505 0.2235 0 -0 0</pose>
        <geometry>
          <box>
            <size>0.02 0.02 0.007</size>
          </box>
        </geometry>
      </visual>
      <visual name='base_link_fixed_joint_lump__lidar_link_visual_7'>
        <pose>0.7 0 0.245 0 -0 0</pose>
        <geometry>
          <cylinder>
            <length>0.05</length>
            <radius>0.05</radius>
          </cylinder>
        </geometry>
      </visual>
      <visual name='base_link_fixed_joint_lump__right_wheel_box_link_visual_8'>
        <pose>0 -0.401 -0.24 1.5708 -0 0</pose>
        <geometry>
          <box>
            <size>1.25 0.4 0.23</size>
          </box>
        </geometry>
        <material>
          <script>
            <name>Gazebo/Black</name>
            <uri>file://media/materials/scripts/gazebo.material</uri>
          </script>
        </material>
      </visual>
      <visual name='base_link_fixed_joint_lump__right_wheel_additional_f_wheel_link_visual_9'>
        <pose>0.625 -0.401 -0.24 1.5708 -0 0</pose>
        <geometry>
          <cylinder>
            <length>0.23</length>
            <radius>0.2</radius>
          </cylinder>
        </geometry>
        <material>
          <script>
            <name>Gazebo/Black</name>
            <uri>file://media/materials/scripts/gazebo.material</uri>
          </script>
        </material>
      </visual>
      <visual name='base_link_fixed_joint_lump__right_wheel_additional_r_wheel_link_visual_10'>
        <pose>-0.625 -0.401 -0.24 1.5708 -0 0</pose>
        <geometry>
          <cylinder>
            <length>0.23</length>
            <radius>0.2</radius>
          </cylinder>
        </geometry>
        <material>
          <script>
            <name>Gazebo/Black</name>
            <uri>file://media/materials/scripts/gazebo.material</uri>
          </script>
        </material>
      </visual>
      <sensor name='imu_sensor' type='imu'>
        <plugin name='imu_plugin' filename='libgazebo_ros_imu_sensor.so'>
          <ros>
            <namespace>/demo</namespace>
            <remapping>~/out:=imu</remapping>
          </ros>
          <initial_orientation_as_reference>0</initial_orientation_as_reference>
        </plugin>
        <always_on>1</always_on>
        <update_rate>100</update_rate>
        <visualize>1</visualize>
        <imu>
          <angular_velocity>
            <x>
              <noise type='gaussian'>
                <mean>0</mean>
                <stddev>0.0002</stddev>
                <bias_mean>7.5e-06</bias_mean>
                <bias_stddev>8e-07</bias_stddev>
              </noise>
            </x>
            <y>
              <noise type='gaussian'>
                <mean>0</mean>
                <stddev>0.0002</stddev>
                <bias_mean>7.5e-06</bias_mean>
                <bias_stddev>8e-07</bias_stddev>
              </noise>
            </y>
            <z>
              <noise type='gaussian'>
                <mean>0</mean>
                <stddev>0.0002</stddev>
                <bias_mean>7.5e-06</bias_mean>
                <bias_stddev>8e-07</bias_stddev>
              </noise>
            </z>
          </angular_velocity>
          <linear_acceleration>
            <x>
              <noise type='gaussian'>
                <mean>0</mean>
                <stddev>0.017</stddev>
                <bias_mean>0.1</bias_mean>
                <bias_stddev>0.001</bias_stddev>
              </noise>
            </x>
            <y>
              <noise type='gaussian'>
                <mean>0</mean>
                <stddev>0.017</stddev>
                <bias_mean>0.1</bias_mean>
                <bias_stddev>0.001</bias_stddev>
              </noise>
            </y>
            <z>
              <noise type='gaussian'>
                <mean>0</mean>
                <stddev>0.017</stddev>
                <bias_mean>0.1</bias_mean>
                <bias_stddev>0.001</bias_stddev>
              </noise>
            </z>
          </linear_acceleration>
        </imu>
        <pose>0.74 -0.505 0.2235 0 -0 0</pose>
      </sensor>
      <sensor name='lidar' type='ray'>
        <always_on>1</always_on>
        <visualize>1</visualize>
        <update_rate>5</update_rate>
        <ray>
          <scan>
            <horizontal>
              <samples>360</samples>
              <resolution>1</resolution>
              <min_angle>1.407</min_angle>
              <max_angle>-1.407</max_angle>
            </horizontal>
          </scan>
          <range>
            <min>0.12</min>
            <max>3.5</max>
            <resolution>0.015</resolution>
          </range>
          <noise>
            <type>gaussian</type>
            <mean>0</mean>
            <stddev>0.01</stddev>
          </noise>
        </ray>
        <plugin name='scan' filename='libgazebo_ros_ray_sensor.so'>
          <ros>
            <remapping>~/out:=scan</remapping>
          </ros>
          <output_type>sensor_msgs/LaserScan</output_type>
          <frame_name>lidar_link</frame_name>
        </plugin>
        <pose>0.7 0 0.245 0 -0 0</pose>
      </sensor>
    </link>
    <joint name='left_wheel_joint' type='revolute'>
      <pose relative_to='base_link'>0 0.4 -0.24 0 -0 0</pose>
      <parent>base_link</parent>
      <child>left_wheel_link</child>
      <axis>
        <xyz>0 1 0</xyz>
        <limit>
          <lower>-1e+16</lower>
          <upper>1e+16</upper>
        </limit>
        <dynamics>
          <spring_reference>0</spring_reference>
          <spring_stiffness>0</spring_stiffness>
        </dynamics>
      </axis>
    </joint>
    <link name='left_wheel_link'>
      <pose relative_to='left_wheel_joint'>0 0 0 0 -0 0</pose>
      <inertial>
        <pose>0 0 0 1.5708 -0 0</pose>
        <mass>25</mass>
        <inertia>
          <ixx>0.360208</ixx>
          <ixy>0</ixy>
          <ixz>0</ixz>
          <iyy>0.360208</iyy>
          <iyz>0</iyz>
          <izz>0.5</izz>
        </inertia>
      </inertial>
      <collision name='left_wheel_link_collision'>
        <pose>0 0 0 1.5708 -0 0</pose>
        <geometry>
          <cylinder>
            <length>0.23</length>
            <radius>0.2</radius>
          </cylinder>
        </geometry>
        <surface>
          <contact>
            <ode/>
          </contact>
          <friction>
            <ode>
              <mu>8000</mu>
              <mu2>8000</mu2>
            </ode>
          </friction>
        </surface>
      </collision>
      <visual name='left_wheel_link_visual'>
        <pose>0 0 0 1.5708 -0 0</pose>
        <geometry>
          <cylinder>
            <length>0.23</length>
            <radius>0.2</radius>
          </cylinder>
        </geometry>
        <material>
          <script>
            <name>Gazebo/Black</name>
            <uri>file://media/materials/scripts/gazebo.material</uri>
          </script>
        </material>
      </visual>
    </link>
    <joint name='right_wheel_joint' type='revolute'>
      <pose relative_to='base_link'>0 -0.4 -0.24 0 -0 0</pose>
      <parent>base_link</parent>
      <child>right_wheel_link</child>
      <axis>
        <xyz>0 1 0</xyz>
        <limit>
          <lower>-1e+16</lower>
          <upper>1e+16</upper>
        </limit>
        <dynamics>
          <spring_reference>0</spring_reference>
          <spring_stiffness>0</spring_stiffness>
        </dynamics>
      </axis>
    </joint>
    <link name='right_wheel_link'>
      <pose relative_to='right_wheel_joint'>0 0 0 0 -0 0</pose>
      <inertial>
        <pose>0 0 0 1.5708 -0 0</pose>
        <mass>25</mass>
        <inertia>
          <ixx>0.360208</ixx>
          <ixy>0</ixy>
          <ixz>0</ixz>
          <iyy>0.360208</iyy>
          <iyz>0</iyz>
          <izz>0.5</izz>
        </inertia>
      </inertial>
      <collision name='right_wheel_link_collision'>
        <pose>0 0 0 1.5708 -0 0</pose>
        <geometry>
          <cylinder>
            <length>0.23</length>
            <radius>0.2</radius>
          </cylinder>
        </geometry>
        <surface>
          <contact>
            <ode/>
          </contact>
          <friction>
            <ode>
              <mu>8000</mu>
              <mu2>8000</mu2>
            </ode>
          </friction>
        </surface>
      </collision>
      <visual name='right_wheel_link_visual'>
        <pose>0 0 0 1.5708 -0 0</pose>
        <geometry>
          <cylinder>
            <length>0.23</length>
            <radius>0.2</radius>
          </cylinder>
        </geometry>
        <material>
          <script>
            <name>Gazebo/Black</name>
            <uri>file://media/materials/scripts/gazebo.material</uri>
          </script>
        </material>
      </visual>
    </link>
    <static>0</static>
    <plugin name='differential_drive_controller' filename='libgazebo_ros_diff_drive.so'>
      <ros>
        <remapping>cmd_vel:=cmd_vel</remapping>
      </ros>
      <update_rate>30</update_rate>
      <left_joint>left_wheel_joint</left_joint>
      <right_joint>right_wheel_joint</right_joint>
      <wheel_separation>0.8</wheel_separation>
      <wheel_diameter>0.4</wheel_diameter>
      <max_wheel_torque>2000</max_wheel_torque>
      <max_wheel_acceleration>2.0</max_wheel_acceleration>
      <command_topic>cmd_vel</command_topic>
      <publish_odom>1</publish_odom>
      <publish_odom_tf>0</publish_odom_tf>
      <publish_wheel_tf>1</publish_wheel_tf>
      <odometry_topic>odom</odometry_topic>
      <odometry_frame>odom</odometry_frame>
      <odometry_source>0</odometry_source>
      <robot_base_frame>base_link</robot_base_frame>
    </plugin>
  </model>
</sdf>
