<?xml version="1.0" ?>
<!-- =================================================================================== -->
<!-- |    This document was autogenerated by xacro from robot_description_gazebo.urdf.xacro | -->
<!-- |    EDITING THIS FILE BY HAND IS NOT RECOMMENDED                                 | -->
<!-- =================================================================================== -->
<robot name="my_robot">
  <!-- Robot Base -->
  <link name="base_link">
    <visual>
      <geometry>
        <box size="1.5 1.03 0.36"/>
      </geometry>
      <material name="White">
        <color rgba="1 1 1 1.0"/>
      </material>
    </visual>
    <collision>
      <geometry>
        <box size="1.5 1.03 0.36"/>
      </geometry>
    </collision>
    <inertial>
      <origin rpy="1.5707963267948966 0 1.5707963267948966" xyz="0 0 0"/>
      <mass value="200"/>
      <inertia ixx="39.660000000000004" ixy="0.0" ixz="0.0" iyy="55.18166666666667" iyz="0.0" izz="19.841666666666665"/>
    </inertial>
  </link>
  <!-- Robot Footprint -->
  <link name="base_footprint">
  </link>
  <joint name="base_joint" type="fixed">
    <parent link="base_link"/>
    <child link="base_footprint"/>
    <origin rpy="0 0 0" xyz="0.0 0.0 -0.16"/>
  </joint>
  <!-- Robot Plate -->
  <link name="plate_link">
    <visual>
      <geometry>
        <box size="1.5 1.03 0.04"/>
      </geometry>
      <material name="Red">
        <color rgba="1 0 0 1.0"/>
      </material>
    </visual>
    <collision>
      <geometry>
        <box size="1.5 1.03 0.04"/>
      </geometry>
    </collision>
    <inertial>
      <origin rpy="1.5707963267948966 0 1.5707963267948966" xyz="0 0 0"/>
      <mass value="10"/>
      <inertia ixx="1.8763333333333332" ixy="0.0" ixz="0.0" iyy="2.7590833333333338" iyz="0.0" izz="0.8854166666666667"/>
    </inertial>
  </link>
  <!-- Plate to Base joint -->
  <joint name="plate_base_joint" type="fixed">
    <parent link="base_link"/>
    <child link="plate_link"/>
    <origin rpy="0 0 0" xyz="0 0 0.19999999999999998"/>
    <!-- <axis xyz="0 0 1"/>
    <limit lower="0" upper="1" effort="1000" velocity="0.1"/> -->
  </joint>
  <link name="left_wheel_link">
    <visual>
      <origin rpy="1.5707963267948966 0 0" xyz="0 0 0"/>
      <geometry>
        <cylinder length="0.23" radius="0.2"/>
      </geometry>
      <material name="Blue">
        <color rgba="0 0 0.5 1.0"/>
      </material>
    </visual>
    <collision>
      <origin rpy="1.5707963267948966 0 0" xyz="0 0 0"/>
      <geometry>
        <cylinder length="0.23" radius="0.2"/>
      </geometry>
    </collision>
    <inertial>
      <origin rpy="1.5707963267948966 0 0" xyz="0 0 0"/>
      <mass value="25"/>
      <inertia ixx="0.3602083333333334" ixy="0" ixz="0" iyy="0.3602083333333334" iyz="0" izz="0.5000000000000001"/>
    </inertial>
  </link>
  <!-- Wheel joint -->
  <joint name="left_wheel_joint" type="continuous">
    <parent link="base_link"/>
    <child link="left_wheel_link"/>
    <origin rpy="0 0 0" xyz="0 0.4 -0.24"/>
    <axis xyz="0 1 0"/>
  </joint>
  <link name="right_wheel_link">
    <visual>
      <origin rpy="1.5707963267948966 0 0" xyz="0 0 0"/>
      <geometry>
        <cylinder length="0.23" radius="0.2"/>
      </geometry>
      <material name="Blue">
        <color rgba="0 0 0.5 1.0"/>
      </material>
    </visual>
    <collision>
      <origin rpy="1.5707963267948966 0 0" xyz="0 0 0"/>
      <geometry>
        <cylinder length="0.23" radius="0.2"/>
      </geometry>
    </collision>
    <inertial>
      <origin rpy="1.5707963267948966 0 0" xyz="0 0 0"/>
      <mass value="25"/>
      <inertia ixx="0.3602083333333334" ixy="0" ixz="0" iyy="0.3602083333333334" iyz="0" izz="0.5000000000000001"/>
    </inertial>
  </link>
  <!-- Wheel joint -->
  <joint name="right_wheel_joint" type="continuous">
    <parent link="base_link"/>
    <child link="right_wheel_link"/>
    <origin rpy="0 0 0" xyz="0 -0.4 -0.24"/>
    <axis xyz="0 1 0"/>
  </joint>
  <!-- Create left and right wheel -->
  <!-- <xacro:wheel_dummy name="left_wheel_dummy" y="${base_width/2 - wheel_width/2}"/>
  <xacro:wheel_dummy name="right_wheel_dummy" y="${-base_width/2 + wheel_width/2}"/> -->
  <link name="left_wheel_box_link">
    <visual>
      <geometry>
        <box size="1.25 0.4 0.23"/>
      </geometry>
      <material name="Blue">
        <color rgba="0 0 0.8 1.0"/>
      </material>
    </visual>
    <collision>
      <geometry>
        <box size="1.25 0.4 0.23"/>
      </geometry>
    </collision>
    <inertial>
      <origin rpy="1.5707963267948966 0 1.5707963267948966" xyz="0 0 0"/>
      <mass value="5"/>
      <inertia ixx="0.9381666666666666" ixy="0.0" ixz="0.0" iyy="1.3795416666666669" iyz="0.0" izz="0.44270833333333337"/>
    </inertial>
  </link>
  <joint name="left_wheel_box_joint" type="fixed">
    <parent link="base_link"/>
    <child link="left_wheel_box_link"/>
    <origin rpy="1.5707963267948966 0 0" xyz="0 0.4 -0.24"/>
  </joint>
  <link name="right_wheel_box_link">
    <visual>
      <geometry>
        <box size="1.25 0.4 0.23"/>
      </geometry>
      <material name="Blue">
        <color rgba="0 0 0.8 1.0"/>
      </material>
    </visual>
    <collision>
      <geometry>
        <box size="1.25 0.4 0.23"/>
      </geometry>
    </collision>
    <inertial>
      <origin rpy="1.5707963267948966 0 1.5707963267948966" xyz="0 0 0"/>
      <mass value="5"/>
      <inertia ixx="0.9381666666666666" ixy="0.0" ixz="0.0" iyy="1.3795416666666669" iyz="0.0" izz="0.44270833333333337"/>
    </inertial>
  </link>
  <joint name="right_wheel_box_joint" type="fixed">
    <parent link="base_link"/>
    <child link="right_wheel_box_link"/>
    <origin rpy="1.5707963267948966 0 0" xyz="0 -0.4 -0.24"/>
  </joint>
  <link name="left_wheel_additional_f_wheel_link">
    <visual>
      <geometry>
        <cylinder length="0.23" radius="0.2"/>
      </geometry>
      <material name="Blue">
        <color rgba="0 0 0.8 1.0"/>
      </material>
    </visual>
    <collision>
      <geometry>
        <cylinder length="0.23" radius="0.2"/>
      </geometry>
    </collision>
    <inertial>
      <origin rpy="1.5707963267948966 0 0" xyz="0 0 0"/>
      <mass value="10"/>
      <inertia ixx="0.14408333333333337" ixy="0" ixz="0" iyy="0.14408333333333337" iyz="0" izz="0.20000000000000004"/>
    </inertial>
  </link>
  <joint name="left_wheel_additional_f_wheel_joint" type="fixed">
    <parent link="left_wheel_box_link"/>
    <child link="left_wheel_additional_f_wheel_link"/>
    <origin rpy="0 0 0" xyz="0.625 0 0"/>
  </joint>
  <link name="right_wheel_additional_f_wheel_link">
    <visual>
      <geometry>
        <cylinder length="0.23" radius="0.2"/>
      </geometry>
      <material name="Blue">
        <color rgba="0 0 0.8 1.0"/>
      </material>
    </visual>
    <collision>
      <geometry>
        <cylinder length="0.23" radius="0.2"/>
      </geometry>
    </collision>
    <inertial>
      <origin rpy="1.5707963267948966 0 0" xyz="0 0 0"/>
      <mass value="10"/>
      <inertia ixx="0.14408333333333337" ixy="0" ixz="0" iyy="0.14408333333333337" iyz="0" izz="0.20000000000000004"/>
    </inertial>
  </link>
  <joint name="right_wheel_additional_f_wheel_joint" type="fixed">
    <parent link="right_wheel_box_link"/>
    <child link="right_wheel_additional_f_wheel_link"/>
    <origin rpy="0 0 0" xyz="0.625 0 0"/>
  </joint>
  <link name="left_wheel_additional_r_wheel_link">
    <visual>
      <geometry>
        <cylinder length="0.23" radius="0.2"/>
      </geometry>
      <material name="Blue">
        <color rgba="0 0 0.8 1.0"/>
      </material>
    </visual>
    <collision>
      <geometry>
        <cylinder length="0.23" radius="0.2"/>
      </geometry>
    </collision>
    <inertial>
      <origin rpy="1.5707963267948966 0 0" xyz="0 0 0"/>
      <mass value="10"/>
      <inertia ixx="0.14408333333333337" ixy="0" ixz="0" iyy="0.14408333333333337" iyz="0" izz="0.20000000000000004"/>
    </inertial>
  </link>
  <joint name="left_wheel_additional_r_wheel_joint" type="fixed">
    <parent link="left_wheel_box_link"/>
    <child link="left_wheel_additional_r_wheel_link"/>
    <origin rpy="0 0 0" xyz="-0.625 0 0"/>
  </joint>
  <link name="right_wheel_additional_r_wheel_link">
    <visual>
      <geometry>
        <cylinder length="0.23" radius="0.2"/>
      </geometry>
      <material name="Blue">
        <color rgba="0 0 0.8 1.0"/>
      </material>
    </visual>
    <collision>
      <geometry>
        <cylinder length="0.23" radius="0.2"/>
      </geometry>
    </collision>
    <inertial>
      <origin rpy="1.5707963267948966 0 0" xyz="0 0 0"/>
      <mass value="10"/>
      <inertia ixx="0.14408333333333337" ixy="0" ixz="0" iyy="0.14408333333333337" iyz="0" izz="0.20000000000000004"/>
    </inertial>
  </link>
  <joint name="right_wheel_additional_r_wheel_joint" type="fixed">
    <parent link="right_wheel_box_link"/>
    <child link="right_wheel_additional_r_wheel_link"/>
    <origin rpy="0 0 0" xyz="-0.625 0 0"/>
  </joint>
  <!-- GPS -->
  <link name="gps_link">
    <visual>
      <geometry>
        <box size="0.15 0.15 0.1"/>
      </geometry>
      <material name="Grey">
        <color rgba="0.5 0.5 .5 1.0"/>
      </material>
    </visual>
    <inertial>
      <origin rpy="1.5707963267948966 0 1.5707963267948966" xyz="0 0 0"/>
      <mass value="2"/>
      <inertia ixx="0.005416666666666667" ixy="0.0" ixz="0.0" iyy="0.0075" iyz="0.0" izz="0.005416666666666667"/>
    </inertial>
  </link>
  <!-- GPS Joint -->
  <joint name="gps_joint" type="fixed">
    <parent link="plate_link"/>
    <child link="gps_link"/>
    <origin rpy="0 0 0" xyz="0.675 0.44 0.07"/>
  </joint>
  <!-- Lidar -->
  <link name="lidar_link">
    <visual>
      <geometry>
        <cylinder length="0.05" radius="0.05"/>
      </geometry>
      <material name="Black">
        <color rgba="0 0 0 1.0"/>
      </material>
    </visual>
    <inertial>
      <origin rpy="1.5707963267948966 0 0" xyz="0 0 0"/>
      <mass value="0.7"/>
      <inertia ixx="0.0005833333333333334" ixy="0" ixz="0" iyy="0.0005833333333333334" iyz="0" izz="0.0008750000000000001"/>
    </inertial>
  </link>
  <!-- Lidar Joint -->
  <joint name="lidar_joint" type="fixed">
    <parent link="plate_link"/>
    <child link="lidar_link"/>
    <origin rpy="0 0 0" xyz="0.7 0 0.045"/>
  </joint>
  <!-- imu -->
  <link name="imu_link">
    <visual>
      <geometry>
        <box size="0.02 0.02 0.007"/>
      </geometry>
      <material name="red">
        <color rgba="0.5 0.2 .2 1.0"/>
      </material>
    </visual>
    <inertial>
      <origin rpy="1.5707963267948966 0 1.5707963267948966" xyz="0 0 0"/>
      <mass value="0.2"/>
      <inertia ixx="0.0005416666666666666" ixy="0.0" ixz="0.0" iyy="0.00075" iyz="0.0" izz="0.0005416666666666666"/>
    </inertial>
  </link>
  <!-- imu Joint -->
  <joint name="imu_joint" type="fixed">
    <parent link="plate_link"/>
    <child link="imu_link"/>
    <origin rpy="0 0 0" xyz="0.74 -0.505 0.0235"/>
  </joint>
  <!-- Gazebo -->
  <gazebo reference="plate_link">
    <material>Gazebo/Red</material>
  </gazebo>
  <gazebo reference="right_wheel_link">
    <material>Gazebo/Black</material>
    <mu1>10000</mu1>
    <mu2>10000</mu2>
  </gazebo>
  <gazebo reference="left_wheel_link">
    <material>Gazebo/Black</material>
    <mu1>10000</mu1>
    <mu2>10000</mu2>
  </gazebo>
  <gazebo>
    <plugin filename="libgazebo_ros_diff_drive.so" name="differential_drive_controller">
      <ros>
        <!-- <namespace></namespace> -->
        <remapping>cmd_vel:=cmd_vel</remapping>
      </ros>
      <update_rate>30</update_rate>
      <left_joint>left_wheel_joint</left_joint>
      <right_joint>right_wheel_joint</right_joint>
      <wheel_separation>0.8</wheel_separation>
      <wheel_diameter>0.4</wheel_diameter>
      <!-- <torque>300</torque> -->
      <max_wheel_torque>2000</max_wheel_torque>
      <max_wheel_acceleration>2.0</max_wheel_acceleration>
      <command_topic>cmd_vel</command_topic>
      <publish_odom>true</publish_odom>
      <publish_odom_tf>false</publish_odom_tf>
      <publish_wheel_tf>true</publish_wheel_tf>
      <odometry_topic>odom</odometry_topic>
      <odometry_frame>odom</odometry_frame>
      <odometry_source>0</odometry_source>
      <robot_base_frame>base_link</robot_base_frame>
    </plugin>
    <!-- <plugin name="joint_state_pub" filename="libgazebo_ros_joint_state_publisher.so">
      <ros>
        <remapping>~/out:=joint_states</remapping>
      </ros>
      <update_rate>30</update_rate>
      <joint_name>left_wheel_joint</joint_name>
      <joint_name>right_wheel_joint</joint_name>
    </plugin>   -->
  </gazebo>
  <!-- <gazebo reference="gps_link">
    <sensor type="gps" name="gps_sensor">
      <update_rate>5.0</update_rate>
      <plugin name="gazebo_ros_gps_plugin" filename="libgazebo_ros_gps.so">
        <topicName>/gps/data</topicName>
        <velocityTopicName>/gps_velocity</velocityTopicName>
      </plugin>
    </sensor>
  </gazebo> -->
  <gazebo reference="lidar_link">
    <sensor name="lidar" type="ray">
      <always_on>true</always_on>
      <visualize>true</visualize>
      <update_rate>5</update_rate>
      <ray>
        <scan>
          <horizontal>
            <samples>360</samples>
            <resolution>1.000000</resolution>
            <min_angle>1.4070000</min_angle>
            <max_angle>-1.4070000</max_angle>
          </horizontal>
        </scan>
        <range>
          <min>0.120000</min>
          <max>3.5</max>
          <resolution>0.015000</resolution>
        </range>
        <noise>
          <type>gaussian</type>
          <mean>0.0</mean>
          <stddev>0.01</stddev>
        </noise>
      </ray>
      <plugin filename="libgazebo_ros_ray_sensor.so" name="scan">
        <ros>
          <remapping>~/out:=scan</remapping>
        </ros>
        <output_type>sensor_msgs/LaserScan</output_type>
        <frame_name>lidar_link</frame_name>
      </plugin>
    </sensor>
  </gazebo>
  <gazebo reference="imu_link">
    <sensor name="imu_sensor" type="imu">
      <plugin filename="libgazebo_ros_imu_sensor.so" name="imu_plugin">
        <ros>
          <namespace>/demo</namespace>
          <remapping>~/out:=imu</remapping>
        </ros>
        <initial_orientation_as_reference>false</initial_orientation_as_reference>
      </plugin>
      <always_on>true</always_on>
      <update_rate>100</update_rate>
      <visualize>true</visualize>
      <imu>
        <angular_velocity>
          <x>
            <noise type="gaussian">
              <mean>0.0</mean>
              <stddev>2e-4</stddev>
              <bias_mean>0.0000075</bias_mean>
              <bias_stddev>0.0000008</bias_stddev>
            </noise>
          </x>
          <y>
            <noise type="gaussian">
              <mean>0.0</mean>
              <stddev>2e-4</stddev>
              <bias_mean>0.0000075</bias_mean>
              <bias_stddev>0.0000008</bias_stddev>
            </noise>
          </y>
          <z>
            <noise type="gaussian">
              <mean>0.0</mean>
              <stddev>2e-4</stddev>
              <bias_mean>0.0000075</bias_mean>
              <bias_stddev>0.0000008</bias_stddev>
            </noise>
          </z>
        </angular_velocity>
        <linear_acceleration>
          <x>
            <noise type="gaussian">
              <mean>0.0</mean>
              <stddev>1.7e-2</stddev>
              <bias_mean>0.1</bias_mean>
              <bias_stddev>0.001</bias_stddev>
            </noise>
          </x>
          <y>
            <noise type="gaussian">
              <mean>0.0</mean>
              <stddev>1.7e-2</stddev>
              <bias_mean>0.1</bias_mean>
              <bias_stddev>0.001</bias_stddev>
            </noise>
          </y>
          <z>
            <noise type="gaussian">
              <mean>0.0</mean>
              <stddev>1.7e-2</stddev>
              <bias_mean>0.1</bias_mean>
              <bias_stddev>0.001</bias_stddev>
            </noise>
          </z>
        </linear_acceleration>
      </imu>
    </sensor>
  </gazebo>
</robot>
